INFO:root:La commande /rate_user a été exécutée.
INFO:root:La commande /rate_user a été exécutée.
ERROR:root:La commande /rate_user a échoué :
Traceback (most recent call last):
  File "D:\OneDrive\Documents\Projets\DiscordBot_TradingCards\bot.py", line 579, in rate_user
    users[evaluated_user_id]["evaluations"].append(evaluation.to_dict())
    ~~~~~~~~~~~~~~~~~~~~~~~~^^^^^^^^^^^^^^^
TypeError: 'User' object is not subscriptable
WARNING:discord.client:PyNaCl is not installed, voice will NOT be supported
INFO:discord.client:logging in using static token
INFO:discord.gateway:Shard ID None has connected to Gateway (Session ID: 5df4fb7be5aa25c43ba7bb6dc34b0bf1).
INFO:root:We have logged in as TestTrade#2680.
INFO:root:La commande /rate_user a été exécutée.
ERROR:root:La commande /rate_user a échoué :
Traceback (most recent call last):
  File "D:\OneDrive\Documents\Projets\DiscordBot_TradingCards\bot.py", line 563, in rate_user
    evaluated_user = User.from_dict(users[evaluated_user_id])
                     ^^^^^^^^^^^^^^^^^^^^^^^^^^^^^^^^^^^^^^^^
  File "D:\OneDrive\Documents\Projets\DiscordBot_TradingCards\classes.py", line 50, in from_dict
    user = cls(data.get('username'))  # Utiliser data.get() pour obtenir la valeur avec une clé donnée ou None si la clé n'existe pas
               ^^^^^^^^
AttributeError: 'User' object has no attribute 'get'
WARNING:discord.client:PyNaCl is not installed, voice will NOT be supported
INFO:discord.client:logging in using static token
INFO:discord.gateway:Shard ID None has connected to Gateway (Session ID: a08c90feaf98baf11609b15179811f4a).
INFO:root:We have logged in as TestTrade#2680.
INFO:root:La commande /rate_user a été exécutée.
ERROR:root:La commande /rate_user a échoué :
Traceback (most recent call last):
  File "D:\OneDrive\Documents\Projets\DiscordBot_TradingCards\bot.py", line 563, in rate_user
    evaluated_user = User.from_dict(users[evaluated_user_id])
                     ^^^^^^^^^^^^^^^^^^^^^^^^^^^^^^^^^^^^^^^^
  File "D:\OneDrive\Documents\Projets\DiscordBot_TradingCards\classes.py", line 50, in from_dict
    user = cls(data['username'])  # Utilisez data['username'] pour obtenir la valeur avec une clé donnée
               ~~~~^^^^^^^^^^^^
TypeError: 'User' object is not subscriptable
WARNING:discord.client:PyNaCl is not installed, voice will NOT be supported
INFO:discord.client:logging in using static token
INFO:discord.gateway:Shard ID None has connected to Gateway (Session ID: 23e23ab9d1cb7c6a41e2bce46bbb238d).
INFO:root:We have logged in as TestTrade#2680.
INFO:root:La commande /rate_user a été exécutée.
ERROR:root:La commande /rate_user a échoué :
Traceback (most recent call last):
  File "D:\OneDrive\Documents\Projets\DiscordBot_TradingCards\bot.py", line 550, in rate_user
    users = load_users()  # Charger les utilisateurs à partir du fichier JSON
            ^^^^^^^^^^^^
  File "D:\OneDrive\Documents\Projets\DiscordBot_TradingCards\functions.py", line 39, in load_users
    user = User(user_data["username"])
           ^^^^^^^^^^^^^^^^^^^^^^^^^^^
TypeError: User.__init__() missing 1 required positional argument: 'username'
WARNING:discord.client:PyNaCl is not installed, voice will NOT be supported
INFO:discord.client:logging in using static token
INFO:discord.gateway:Shard ID None has connected to Gateway (Session ID: 68bfd8bec04270fcce13bab692a35f74).
INFO:root:We have logged in as TestTrade#2680.
INFO:root:La commande /rate_user a été exécutée.
ERROR:root:La commande /rate_user a échoué :
Traceback (most recent call last):
  File "D:\OneDrive\Documents\Projets\DiscordBot_TradingCards\bot.py", line 563, in rate_user
    evaluated_user = User.from_dict(users[evaluated_user_id])
                     ^^^^^^^^^^^^^^^^^^^^^^^^^^^^^^^^^^^^^^^^
  File "D:\OneDrive\Documents\Projets\DiscordBot_TradingCards\classes.py", line 52, in from_dict
    user = cls(data['user_id'], data['username'])
               ~~~~^^^^^^^^^^^
TypeError: 'User' object is not subscriptable
WARNING:discord.client:PyNaCl is not installed, voice will NOT be supported
INFO:discord.client:logging in using static token
INFO:discord.gateway:Shard ID None has connected to Gateway (Session ID: 0ed570044299fae759212146d1d85c3c).
INFO:root:We have logged in as TestTrade#2680.
INFO:root:La commande /rate_user a été exécutée.
ERROR:root:La commande /rate_user a échoué :
Traceback (most recent call last):
  File "D:\OneDrive\Documents\Projets\DiscordBot_TradingCards\bot.py", line 549, in rate_user
    users = load_users()
            ^^^^^^^^^^^^
  File "D:\OneDrive\Documents\Projets\DiscordBot_TradingCards\functions.py", line 32, in load_users
    user = User.from_dict(user_data)  # Utiliser la méthode from_dict() de la classe User
           ^^^^^^^^^^^^^^^^^^^^^^^^^
  File "D:\OneDrive\Documents\Projets\DiscordBot_TradingCards\classes.py", line 49, in from_dict
    user.searches = [Card(card_info['card_number'], card_info['name'], card_info['rarity'], card_info['image_url']) for card_info in data['searches']]
                    ^^^^^^^^^^^^^^^^^^^^^^^^^^^^^^^^^^^^^^^^^^^^^^^^^^^^^^^^^^^^^^^^^^^^^^^^^^^^^^^^^^^^^^^^^^^^^^^^^^^^^^^^^^^^^^^^^^^^^^^^^^^^^^^^^^
  File "D:\OneDrive\Documents\Projets\DiscordBot_TradingCards\classes.py", line 49, in <listcomp>
    user.searches = [Card(card_info['card_number'], card_info['name'], card_info['rarity'], card_info['image_url']) for card_info in data['searches']]
                          ~~~~~~~~~^^^^^^^^^^^^^^^
TypeError: string indices must be integers, not 'str'
INFO:root:La commande /rate_user a été exécutée.
ERROR:root:La commande /rate_user a échoué :
Traceback (most recent call last):
  File "D:\OneDrive\Documents\Projets\DiscordBot_TradingCards\bot.py", line 549, in rate_user
    users = load_users()
            ^^^^^^^^^^^^
  File "D:\OneDrive\Documents\Projets\DiscordBot_TradingCards\functions.py", line 32, in load_users
    user = User.from_dict(user_data)  # Utiliser la méthode from_dict() de la classe User
           ^^^^^^^^^^^^^^^^^^^^^^^^^
  File "D:\OneDrive\Documents\Projets\DiscordBot_TradingCards\classes.py", line 49, in from_dict
    user.searches = [Card(card_info['card_number'], card_info['name'], card_info['rarity'], card_info['image_url']) for card_info in data['searches']]
                    ^^^^^^^^^^^^^^^^^^^^^^^^^^^^^^^^^^^^^^^^^^^^^^^^^^^^^^^^^^^^^^^^^^^^^^^^^^^^^^^^^^^^^^^^^^^^^^^^^^^^^^^^^^^^^^^^^^^^^^^^^^^^^^^^^^
  File "D:\OneDrive\Documents\Projets\DiscordBot_TradingCards\classes.py", line 49, in <listcomp>
    user.searches = [Card(card_info['card_number'], card_info['name'], card_info['rarity'], card_info['image_url']) for card_info in data['searches']]
                          ~~~~~~~~~^^^^^^^^^^^^^^^
TypeError: string indices must be integers, not 'str'
WARNING:discord.client:PyNaCl is not installed, voice will NOT be supported
INFO:discord.client:logging in using static token
INFO:discord.gateway:Shard ID None has connected to Gateway (Session ID: fb3db779b247296dce45d5e01a4de80a).
INFO:root:We have logged in as TestTrade#2680.
INFO:root:La commande /rate_user a été exécutée.
ERROR:root:La commande /rate_user a échoué :
Traceback (most recent call last):
  File "D:\OneDrive\Documents\Projets\DiscordBot_TradingCards\bot.py", line 549, in rate_user
    users = load_users()
            ^^^^^^^^^^^^
  File "D:\OneDrive\Documents\Projets\DiscordBot_TradingCards\functions.py", line 32, in load_users
    user = User.from_dict(user_data)  # Utiliser la méthode from_dict() de la classe User
           ^^^^^^^^^^^^^^^^^^^^^^^^^
  File "D:\OneDrive\Documents\Projets\DiscordBot_TradingCards\classes.py", line 51, in from_dict
    user.searches = [Card(card_info['card_number'], card_info['name'], card_info['rarity'], card_info['image_url']) for card_info in data['searches']]
                    ^^^^^^^^^^^^^^^^^^^^^^^^^^^^^^^^^^^^^^^^^^^^^^^^^^^^^^^^^^^^^^^^^^^^^^^^^^^^^^^^^^^^^^^^^^^^^^^^^^^^^^^^^^^^^^^^^^^^^^^^^^^^^^^^^^
  File "D:\OneDrive\Documents\Projets\DiscordBot_TradingCards\classes.py", line 51, in <listcomp>
    user.searches = [Card(card_info['card_number'], card_info['name'], card_info['rarity'], card_info['image_url']) for card_info in data['searches']]
                          ~~~~~~~~~^^^^^^^^^^^^^^^
TypeError: string indices must be integers, not 'str'
WARNING:discord.client:PyNaCl is not installed, voice will NOT be supported
INFO:discord.client:logging in using static token
INFO:discord.gateway:Shard ID None has connected to Gateway (Session ID: f3a645dcf1f2591882c4bbe0034c5968).
INFO:root:We have logged in as TestTrade#2680.
INFO:root:La commande /rate_user a été exécutée.
INFO:root:La commande /rate_user a été exécutée.
WARNING:discord.client:PyNaCl is not installed, voice will NOT be supported
INFO:discord.client:logging in using static token
INFO:discord.gateway:Shard ID None has connected to Gateway (Session ID: 28126975d276e7e5c7dafd26beb3b143).
INFO:root:We have logged in as TestTrade#2680.
WARNING:discord.client:PyNaCl is not installed, voice will NOT be supported
INFO:discord.client:logging in using static token
INFO:discord.gateway:Shard ID None has connected to Gateway (Session ID: 2920cafb9f43ead42c86e83df1e9cc2b).
INFO:root:We have logged in as TestTrade#2680.
INFO:root:La commande /rate_user a été exécutée.
INFO:root:La commande /rate_user a été exécutée.
WARNING:discord.client:PyNaCl is not installed, voice will NOT be supported
INFO:discord.client:logging in using static token
INFO:discord.gateway:Shard ID None has connected to Gateway (Session ID: 314648a316589e237febcf2b6f221096).
INFO:root:We have logged in as TestTrade#2680.
INFO:root:La commande /rate_user a été exécutée.
ERROR:root:La commande /rate_user a échoué :
Traceback (most recent call last):
  File "D:\OneDrive\Documents\Projets\DiscordBot_TradingCards\bot.py", line 575, in rate_user
    evaluated_user.add_evaluation(evaluation)
  File "D:\OneDrive\Documents\Projets\DiscordBot_TradingCards\classes.py", line 58, in add_evaluation
    self.evaluations.extend(evaluation)
TypeError: 'Evaluation' object is not iterable
WARNING:discord.client:PyNaCl is not installed, voice will NOT be supported
INFO:discord.client:logging in using static token
INFO:discord.gateway:Shard ID None has connected to Gateway (Session ID: cb39b60be7c72f97e1226881a743da4f).
INFO:root:We have logged in as TestTrade#2680.
INFO:root:La commande /rate_user a été exécutée.
WARNING:discord.client:PyNaCl is not installed, voice will NOT be supported
INFO:discord.client:logging in using static token
INFO:discord.gateway:Shard ID None has connected to Gateway (Session ID: 6bf845cdb62c6d0752340d360fd58b45).
INFO:root:We have logged in as TestTrade#2680.
INFO:root:La commande /rate_user a été exécutée.
WARNING:discord.client:PyNaCl is not installed, voice will NOT be supported
INFO:discord.client:logging in using static token
INFO:discord.gateway:Shard ID None has connected to Gateway (Session ID: ed52109724710fc675a5d489b99466ca).
INFO:root:We have logged in as TestTrade#2680.
INFO:root:La commande /rate_user a été exécutée.
WARNING:discord.client:PyNaCl is not installed, voice will NOT be supported
INFO:discord.client:logging in using static token
INFO:discord.gateway:Shard ID None has connected to Gateway (Session ID: 96e8096abc12fb722535fc35e3651cb4).
INFO:root:We have logged in as TestTrade#2680.
WARNING:discord.client:PyNaCl is not installed, voice will NOT be supported
INFO:discord.client:logging in using static token
INFO:discord.gateway:Shard ID None has connected to Gateway (Session ID: 347fe8266fa7e6e94b3a10f2c5d35928).
INFO:root:La commande /rate_user a été exécutée.
ERROR:root:La commande /rate_user a échoué :
Traceback (most recent call last):
  File "D:\OneDrive\Documents\Projets\DiscordBot_TradingCards\bot.py", line 572, in rate_user
    evaluation = Evaluation(evaluator_username, rating, comment, cards_sent.split(",") if cards_sent else [])
                 ^^^^^^^^^^
NameError: name 'Evaluation' is not defined
WARNING:discord.client:PyNaCl is not installed, voice will NOT be supported
INFO:discord.client:logging in using static token
INFO:discord.gateway:Shard ID None has connected to Gateway (Session ID: e11db3f5bf18b6c72a8f7223cc87887f).
INFO:root:La commande /rate_user a été exécutée.
INFO:root:La commande /rate_user a été exécutée.
INFO:root:We have logged in as TestTrade#2680.
WARNING:discord.client:PyNaCl is not installed, voice will NOT be supported
INFO:discord.client:logging in using static token
INFO:discord.gateway:Shard ID None has connected to Gateway (Session ID: 450d8aad7f50679f8288883e45923b82).
INFO:root:We have logged in as TestTrade#2680.
INFO:root:La commande /rate_user a été exécutée.
INFO:root:La commande /rate_user a été exécutée.
WARNING:discord.client:PyNaCl is not installed, voice will NOT be supported
INFO:discord.client:logging in using static token
INFO:discord.gateway:Shard ID None has connected to Gateway (Session ID: 20ba391ef243c9db98c359e019412565).
INFO:root:We have logged in as TestTrade#2680.
INFO:root:La commande /rate_user a été exécutée.
INFO:root:La commande /rate_user a été exécutée.
INFO:root:La commande /rate_user a été exécutée.
INFO:root:La commande /rate_user a été exécutée.
WARNING:discord.client:PyNaCl is not installed, voice will NOT be supported
INFO:discord.client:logging in using static token
INFO:discord.gateway:Shard ID None has connected to Gateway (Session ID: 739e74f5eb1d2e1551b42eb6f36b2bb2).
INFO:root:We have logged in as TestTrade#2680.
INFO:root:La commande /rate_user a été exécutée.
WARNING:discord.client:PyNaCl is not installed, voice will NOT be supported
INFO:discord.client:logging in using static token
INFO:discord.gateway:Shard ID None has connected to Gateway (Session ID: 0072dadfd4bf35355c71860cfb7fcd8e).
INFO:root:We have logged in as TestTrade#2680.
INFO:root:La commande /rate_user a été exécutée.
INFO:root:La commande /rate_user a été exécutée.
INFO:root:La commande /rate_user a été exécutée.
WARNING:discord.client:PyNaCl is not installed, voice will NOT be supported
INFO:discord.client:logging in using static token
INFO:discord.gateway:Shard ID None has connected to Gateway (Session ID: b8c2b58426c5b17dd3b647c551406918).
INFO:root:We have logged in as TestTrade#2680.
INFO:root:La commande /show_evaluations a été exécutée.
WARNING:discord.client:PyNaCl is not installed, voice will NOT be supported
INFO:discord.client:logging in using static token
INFO:discord.gateway:Shard ID None has connected to Gateway (Session ID: bd613b1557e70f60a1eb29f2af30b1ff).
INFO:root:We have logged in as TestTrade#2680.
INFO:root:La commande /show_evaluations a été exécutée.
INFO:root:La commande /show_evaluations a été exécutée.
WARNING:discord.client:PyNaCl is not installed, voice will NOT be supported
INFO:discord.client:logging in using static token
INFO:discord.gateway:Shard ID None has connected to Gateway (Session ID: 2bc5bfb1bd6baeb583a5370ba1c6a070).
INFO:root:We have logged in as TestTrade#2680.
INFO:root:La commande /show_evaluations a été exécutée.
ERROR:root:La commande /show_evaluations a échoué :
Traceback (most recent call last):
  File "D:\OneDrive\Documents\Projets\DiscordBot_TradingCards\bot.py", line 606, in show_evaluations
    cards_info = [f"Cartes échangées : {card.card_number} {card.name}" for card in evaluation.traded_cards]
                                                                                   ^^^^^^^^^^^^^^^^^^^^^^^
AttributeError: 'Evaluation' object has no attribute 'traded_cards'
WARNING:discord.client:PyNaCl is not installed, voice will NOT be supported
INFO:discord.client:logging in using static token
INFO:discord.gateway:Shard ID None has connected to Gateway (Session ID: 65c8262af31058390e9cbde28a2dab26).
INFO:root:We have logged in as TestTrade#2680.
INFO:root:La commande /show_evaluations a été exécutée.
WARNING:discord.client:PyNaCl is not installed, voice will NOT be supported
INFO:discord.client:logging in using static token
INFO:discord.gateway:Shard ID None has connected to Gateway (Session ID: 2334a32e687b1eb415cde94b3329a93c).
INFO:root:We have logged in as TestTrade#2680.
INFO:root:La commande /show_evaluations a été exécutée.
WARNING:discord.client:PyNaCl is not installed, voice will NOT be supported
INFO:discord.client:logging in using static token
INFO:discord.gateway:Shard ID None has connected to Gateway (Session ID: 9c2601211cef221f7bcc4825889259d1).
INFO:root:We have logged in as TestTrade#2680.
INFO:root:La commande /show_evaluations a été exécutée.
WARNING:discord.client:PyNaCl is not installed, voice will NOT be supported
INFO:discord.client:logging in using static token
INFO:discord.gateway:Shard ID None has connected to Gateway (Session ID: 4cee0f1ab2019cc42048138675d06ccc).
INFO:root:We have logged in as TestTrade#2680.
INFO:root:La commande /show_evaluations a été exécutée.
WARNING:discord.client:PyNaCl is not installed, voice will NOT be supported
INFO:discord.client:logging in using static token
INFO:discord.gateway:Shard ID None has connected to Gateway (Session ID: fec5d9ebffba3c376c71538ba277f94f).
INFO:root:We have logged in as TestTrade#2680.
INFO:root:La commande /show_evaluations a été exécutée.
INFO:root:La commande /rate_user a été exécutée.
INFO:root:La commande /rate_user a été exécutée.
WARNING:discord.client:PyNaCl is not installed, voice will NOT be supported
INFO:discord.client:logging in using static token
INFO:discord.gateway:Shard ID None has connected to Gateway (Session ID: a0369edbf77d1e3a781dcf06f52e2739).
INFO:root:We have logged in as TestTrade#2680.
INFO:root:La commande /rate_user a été exécutée.
ERROR:root:La commande /rate_user a échoué :
Traceback (most recent call last):
  File "D:\OneDrive\Documents\Projets\DiscordBot_TradingCards\bot.py", line 585, in rate_user
    await evaluated_user.send(confirmation_message)
          ^^^^^^^^^^^^^^^^^^^
AttributeError: 'User' object has no attribute 'send'
ERROR:discord.app_commands.tree:Ignoring exception in command 'rate_user'
Traceback (most recent call last):
  File "D:\OneDrive\Documents\Projets\DiscordBot_TradingCards\bot.py", line 585, in rate_user
    await evaluated_user.send(confirmation_message)
          ^^^^^^^^^^^^^^^^^^^
AttributeError: 'User' object has no attribute 'send'

During handling of the above exception, another exception occurred:

Traceback (most recent call last):
  File "C:\Users\Lupink\AppData\Local\Programs\Python\Python311\Lib\site-packages\discord\app_commands\commands.py", line 828, in _do_call
    return await self._callback(interaction, **params)  # type: ignore
           ^^^^^^^^^^^^^^^^^^^^^^^^^^^^^^^^^^^^^^^^^^^
  File "D:\OneDrive\Documents\Projets\DiscordBot_TradingCards\bot.py", line 590, in rate_user
    await interaction.response.send_message("Une erreur est survenue lors de l'exécution de la commande.", ephemeral=True)
  File "C:\Users\Lupink\AppData\Local\Programs\Python\Python311\Lib\site-packages\discord\interactions.py", line 774, in send_message
    raise InteractionResponded(self._parent)
discord.errors.InteractionResponded: This interaction has already been responded to before

The above exception was the direct cause of the following exception:

Traceback (most recent call last):
  File "C:\Users\Lupink\AppData\Local\Programs\Python\Python311\Lib\site-packages\discord\app_commands\tree.py", line 1248, in _call
    await command._invoke_with_namespace(interaction, namespace)
  File "C:\Users\Lupink\AppData\Local\Programs\Python\Python311\Lib\site-packages\discord\app_commands\commands.py", line 853, in _invoke_with_namespace
    return await self._do_call(interaction, transformed_values)
           ^^^^^^^^^^^^^^^^^^^^^^^^^^^^^^^^^^^^^^^^^^^^^^^^^^^^
  File "C:\Users\Lupink\AppData\Local\Programs\Python\Python311\Lib\site-packages\discord\app_commands\commands.py", line 846, in _do_call
    raise CommandInvokeError(self, e) from e
discord.app_commands.errors.CommandInvokeError: Command 'rate_user' raised an exception: InteractionResponded: This interaction has already been responded to before
WARNING:discord.client:PyNaCl is not installed, voice will NOT be supported
INFO:discord.client:logging in using static token
INFO:discord.gateway:Shard ID None has connected to Gateway (Session ID: 1f63eabd701c5127e1319550fcf3e7d3).
INFO:root:We have logged in as TestTrade#2680.
INFO:root:La commande /rate_user a été exécutée.
WARNING:discord.client:PyNaCl is not installed, voice will NOT be supported
INFO:discord.client:logging in using static token
INFO:discord.gateway:Shard ID None has connected to Gateway (Session ID: 939d0a5db49a21b162b73c26dd31d826).
INFO:root:We have logged in as TestTrade#2680.
INFO:root:La commande /rate_user a été exécutée.
ERROR:root:La commande /rate_user a échoué :
Traceback (most recent call last):
  File "D:\OneDrive\Documents\Projets\DiscordBot_TradingCards\bot.py", line 585, in rate_user
    await evaluated_user.send(confirmation_message)
          ^^^^^^^^^^^^^^^^^^^
AttributeError: 'User' object has no attribute 'send'
ERROR:discord.app_commands.tree:Ignoring exception in command 'rate_user'
Traceback (most recent call last):
  File "D:\OneDrive\Documents\Projets\DiscordBot_TradingCards\bot.py", line 585, in rate_user
    await evaluated_user.send(confirmation_message)
          ^^^^^^^^^^^^^^^^^^^
AttributeError: 'User' object has no attribute 'send'

During handling of the above exception, another exception occurred:

Traceback (most recent call last):
  File "C:\Users\Lupink\AppData\Local\Programs\Python\Python311\Lib\site-packages\discord\app_commands\commands.py", line 828, in _do_call
    return await self._callback(interaction, **params)  # type: ignore
           ^^^^^^^^^^^^^^^^^^^^^^^^^^^^^^^^^^^^^^^^^^^
  File "D:\OneDrive\Documents\Projets\DiscordBot_TradingCards\bot.py", line 590, in rate_user
    await interaction.response.send_message("Une erreur est survenue lors de l'exécution de la commande.", ephemeral=True)
  File "C:\Users\Lupink\AppData\Local\Programs\Python\Python311\Lib\site-packages\discord\interactions.py", line 774, in send_message
    raise InteractionResponded(self._parent)
discord.errors.InteractionResponded: This interaction has already been responded to before

The above exception was the direct cause of the following exception:

Traceback (most recent call last):
  File "C:\Users\Lupink\AppData\Local\Programs\Python\Python311\Lib\site-packages\discord\app_commands\tree.py", line 1248, in _call
    await command._invoke_with_namespace(interaction, namespace)
  File "C:\Users\Lupink\AppData\Local\Programs\Python\Python311\Lib\site-packages\discord\app_commands\commands.py", line 853, in _invoke_with_namespace
    return await self._do_call(interaction, transformed_values)
           ^^^^^^^^^^^^^^^^^^^^^^^^^^^^^^^^^^^^^^^^^^^^^^^^^^^^
  File "C:\Users\Lupink\AppData\Local\Programs\Python\Python311\Lib\site-packages\discord\app_commands\commands.py", line 846, in _do_call
    raise CommandInvokeError(self, e) from e
discord.app_commands.errors.CommandInvokeError: Command 'rate_user' raised an exception: InteractionResponded: This interaction has already been responded to before
WARNING:discord.client:PyNaCl is not installed, voice will NOT be supported
INFO:discord.client:logging in using static token
INFO:discord.gateway:Shard ID None has connected to Gateway (Session ID: 8b65869db0036db576cb60d4ddfdf25a).
INFO:root:We have logged in as TestTrade#2680.
INFO:root:La commande /rate_user a été exécutée.
ERROR:root:La commande /rate_user a échoué :
Traceback (most recent call last):
  File "D:\OneDrive\Documents\Projets\DiscordBot_TradingCards\bot.py", line 586, in rate_user
    dm = await evaluated_user.user.create_dm()
               ^^^^^^^^^^^^^^^^^^^
AttributeError: 'User' object has no attribute 'user'
ERROR:discord.app_commands.tree:Ignoring exception in command 'rate_user'
Traceback (most recent call last):
  File "D:\OneDrive\Documents\Projets\DiscordBot_TradingCards\bot.py", line 586, in rate_user
    dm = await evaluated_user.user.create_dm()
               ^^^^^^^^^^^^^^^^^^^
AttributeError: 'User' object has no attribute 'user'

During handling of the above exception, another exception occurred:

Traceback (most recent call last):
  File "C:\Users\Lupink\AppData\Local\Programs\Python\Python311\Lib\site-packages\discord\app_commands\commands.py", line 828, in _do_call
    return await self._callback(interaction, **params)  # type: ignore
           ^^^^^^^^^^^^^^^^^^^^^^^^^^^^^^^^^^^^^^^^^^^
  File "D:\OneDrive\Documents\Projets\DiscordBot_TradingCards\bot.py", line 591, in rate_user
    await interaction.response.send_message("Une erreur est survenue lors de l'exécution de la commande.", ephemeral=True)
  File "C:\Users\Lupink\AppData\Local\Programs\Python\Python311\Lib\site-packages\discord\interactions.py", line 774, in send_message
    raise InteractionResponded(self._parent)
discord.errors.InteractionResponded: This interaction has already been responded to before

The above exception was the direct cause of the following exception:

Traceback (most recent call last):
  File "C:\Users\Lupink\AppData\Local\Programs\Python\Python311\Lib\site-packages\discord\app_commands\tree.py", line 1248, in _call
    await command._invoke_with_namespace(interaction, namespace)
  File "C:\Users\Lupink\AppData\Local\Programs\Python\Python311\Lib\site-packages\discord\app_commands\commands.py", line 853, in _invoke_with_namespace
    return await self._do_call(interaction, transformed_values)
           ^^^^^^^^^^^^^^^^^^^^^^^^^^^^^^^^^^^^^^^^^^^^^^^^^^^^
  File "C:\Users\Lupink\AppData\Local\Programs\Python\Python311\Lib\site-packages\discord\app_commands\commands.py", line 846, in _do_call
    raise CommandInvokeError(self, e) from e
discord.app_commands.errors.CommandInvokeError: Command 'rate_user' raised an exception: InteractionResponded: This interaction has already been responded to before
WARNING:discord.client:PyNaCl is not installed, voice will NOT be supported
INFO:discord.client:logging in using static token
INFO:discord.gateway:Shard ID None has connected to Gateway (Session ID: c9379ea400f998a18f5de8c79009784d).
INFO:root:We have logged in as TestTrade#2680.
INFO:root:La commande /rate_user a été exécutée.
ERROR:root:La commande /rate_user a échoué :
Traceback (most recent call last):
  File "D:\OneDrive\Documents\Projets\DiscordBot_TradingCards\bot.py", line 586, in rate_user
    dm = await evaluated_user.create_dm()
               ^^^^^^^^^^^^^^^^^^^^^^^^
AttributeError: 'User' object has no attribute 'create_dm'
ERROR:discord.app_commands.tree:Ignoring exception in command 'rate_user'
Traceback (most recent call last):
  File "D:\OneDrive\Documents\Projets\DiscordBot_TradingCards\bot.py", line 586, in rate_user
    dm = await evaluated_user.create_dm()
               ^^^^^^^^^^^^^^^^^^^^^^^^
AttributeError: 'User' object has no attribute 'create_dm'

During handling of the above exception, another exception occurred:

Traceback (most recent call last):
  File "C:\Users\Lupink\AppData\Local\Programs\Python\Python311\Lib\site-packages\discord\app_commands\commands.py", line 828, in _do_call
    return await self._callback(interaction, **params)  # type: ignore
           ^^^^^^^^^^^^^^^^^^^^^^^^^^^^^^^^^^^^^^^^^^^
  File "D:\OneDrive\Documents\Projets\DiscordBot_TradingCards\bot.py", line 591, in rate_user
    await interaction.response.send_message("Une erreur est survenue lors de l'exécution de la commande.", ephemeral=True)
  File "C:\Users\Lupink\AppData\Local\Programs\Python\Python311\Lib\site-packages\discord\interactions.py", line 774, in send_message
    raise InteractionResponded(self._parent)
discord.errors.InteractionResponded: This interaction has already been responded to before

The above exception was the direct cause of the following exception:

Traceback (most recent call last):
  File "C:\Users\Lupink\AppData\Local\Programs\Python\Python311\Lib\site-packages\discord\app_commands\tree.py", line 1248, in _call
    await command._invoke_with_namespace(interaction, namespace)
  File "C:\Users\Lupink\AppData\Local\Programs\Python\Python311\Lib\site-packages\discord\app_commands\commands.py", line 853, in _invoke_with_namespace
    return await self._do_call(interaction, transformed_values)
           ^^^^^^^^^^^^^^^^^^^^^^^^^^^^^^^^^^^^^^^^^^^^^^^^^^^^
  File "C:\Users\Lupink\AppData\Local\Programs\Python\Python311\Lib\site-packages\discord\app_commands\commands.py", line 846, in _do_call
    raise CommandInvokeError(self, e) from e
discord.app_commands.errors.CommandInvokeError: Command 'rate_user' raised an exception: InteractionResponded: This interaction has already been responded to before
WARNING:discord.client:PyNaCl is not installed, voice will NOT be supported
INFO:discord.client:logging in using static token
INFO:discord.gateway:Shard ID None has connected to Gateway (Session ID: 39c37e1499252333acf4d36ce2ac6928).
INFO:root:We have logged in as TestTrade#2680.
INFO:root:La commande /rate_user a été exécutée.
ERROR:root:La commande /rate_user a échoué :
Traceback (most recent call last):
  File "D:\OneDrive\Documents\Projets\DiscordBot_TradingCards\bot.py", line 586, in rate_user
    dm = await evaluated_user.create_dm()
               ^^^^^^^^^^^^^^^^^^^^^^^^
AttributeError: 'User' object has no attribute 'create_dm'
ERROR:discord.app_commands.tree:Ignoring exception in command 'rate_user'
Traceback (most recent call last):
  File "D:\OneDrive\Documents\Projets\DiscordBot_TradingCards\bot.py", line 586, in rate_user
    dm = await evaluated_user.create_dm()
               ^^^^^^^^^^^^^^^^^^^^^^^^
AttributeError: 'User' object has no attribute 'create_dm'

During handling of the above exception, another exception occurred:

Traceback (most recent call last):
  File "C:\Users\Lupink\AppData\Local\Programs\Python\Python311\Lib\site-packages\discord\app_commands\commands.py", line 828, in _do_call
    return await self._callback(interaction, **params)  # type: ignore
           ^^^^^^^^^^^^^^^^^^^^^^^^^^^^^^^^^^^^^^^^^^^
  File "D:\OneDrive\Documents\Projets\DiscordBot_TradingCards\bot.py", line 591, in rate_user
    await interaction.response.send_message("Une erreur est survenue lors de l'exécution de la commande.", ephemeral=True)
  File "C:\Users\Lupink\AppData\Local\Programs\Python\Python311\Lib\site-packages\discord\interactions.py", line 774, in send_message
    raise InteractionResponded(self._parent)
discord.errors.InteractionResponded: This interaction has already been responded to before

The above exception was the direct cause of the following exception:

Traceback (most recent call last):
  File "C:\Users\Lupink\AppData\Local\Programs\Python\Python311\Lib\site-packages\discord\app_commands\tree.py", line 1248, in _call
    await command._invoke_with_namespace(interaction, namespace)
  File "C:\Users\Lupink\AppData\Local\Programs\Python\Python311\Lib\site-packages\discord\app_commands\commands.py", line 853, in _invoke_with_namespace
    return await self._do_call(interaction, transformed_values)
           ^^^^^^^^^^^^^^^^^^^^^^^^^^^^^^^^^^^^^^^^^^^^^^^^^^^^
  File "C:\Users\Lupink\AppData\Local\Programs\Python\Python311\Lib\site-packages\discord\app_commands\commands.py", line 846, in _do_call
    raise CommandInvokeError(self, e) from e
discord.app_commands.errors.CommandInvokeError: Command 'rate_user' raised an exception: InteractionResponded: This interaction has already been responded to before
WARNING:discord.client:PyNaCl is not installed, voice will NOT be supported
INFO:discord.client:logging in using static token
INFO:discord.gateway:Shard ID None has connected to Gateway (Session ID: 79edb040583b15a6721abdcb69886b34).
INFO:root:We have logged in as TestTrade#2680.
INFO:root:La commande /rate_user a été exécutée.
ERROR:root:La commande /rate_user a échoué :
Traceback (most recent call last):
  File "D:\OneDrive\Documents\Projets\DiscordBot_TradingCards\bot.py", line 585, in rate_user
    to = await client.fetch_user(int(evaluated_user))
                                 ^^^^^^^^^^^^^^^^^^^
TypeError: int() argument must be a string, a bytes-like object or a real number, not 'User'
ERROR:discord.app_commands.tree:Ignoring exception in command 'rate_user'
Traceback (most recent call last):
  File "D:\OneDrive\Documents\Projets\DiscordBot_TradingCards\bot.py", line 585, in rate_user
    to = await client.fetch_user(int(evaluated_user))
                                 ^^^^^^^^^^^^^^^^^^^
TypeError: int() argument must be a string, a bytes-like object or a real number, not 'User'

During handling of the above exception, another exception occurred:

Traceback (most recent call last):
  File "C:\Users\Lupink\AppData\Local\Programs\Python\Python311\Lib\site-packages\discord\app_commands\commands.py", line 828, in _do_call
    return await self._callback(interaction, **params)  # type: ignore
           ^^^^^^^^^^^^^^^^^^^^^^^^^^^^^^^^^^^^^^^^^^^
  File "D:\OneDrive\Documents\Projets\DiscordBot_TradingCards\bot.py", line 592, in rate_user
    await interaction.response.send_message("Une erreur est survenue lors de l'exécution de la commande.", ephemeral=True)
  File "C:\Users\Lupink\AppData\Local\Programs\Python\Python311\Lib\site-packages\discord\interactions.py", line 774, in send_message
    raise InteractionResponded(self._parent)
discord.errors.InteractionResponded: This interaction has already been responded to before

The above exception was the direct cause of the following exception:

Traceback (most recent call last):
  File "C:\Users\Lupink\AppData\Local\Programs\Python\Python311\Lib\site-packages\discord\app_commands\tree.py", line 1248, in _call
    await command._invoke_with_namespace(interaction, namespace)
  File "C:\Users\Lupink\AppData\Local\Programs\Python\Python311\Lib\site-packages\discord\app_commands\commands.py", line 853, in _invoke_with_namespace
    return await self._do_call(interaction, transformed_values)
           ^^^^^^^^^^^^^^^^^^^^^^^^^^^^^^^^^^^^^^^^^^^^^^^^^^^^
  File "C:\Users\Lupink\AppData\Local\Programs\Python\Python311\Lib\site-packages\discord\app_commands\commands.py", line 846, in _do_call
    raise CommandInvokeError(self, e) from e
discord.app_commands.errors.CommandInvokeError: Command 'rate_user' raised an exception: InteractionResponded: This interaction has already been responded to before
INFO:discord.gateway:Shard ID None has successfully RESUMED session 79edb040583b15a6721abdcb69886b34.
WARNING:discord.client:PyNaCl is not installed, voice will NOT be supported
INFO:discord.client:logging in using static token
INFO:discord.gateway:Shard ID None has connected to Gateway (Session ID: ef5bd0aef5750b86753d282d6f8d042c).
INFO:root:We have logged in as TestTrade#2680.
WARNING:discord.client:PyNaCl is not installed, voice will NOT be supported
INFO:discord.client:logging in using static token
INFO:discord.gateway:Shard ID None has connected to Gateway (Session ID: 641229dfd9f35707d5aa95fc12f866f1).
INFO:root:La commande /rate_user a été exécutée.
ERROR:root:La commande /rate_user a échoué :
Traceback (most recent call last):
  File "D:\OneDrive\Documents\Projets\DiscordBot_TradingCards\bot.py", line 585, in rate_user
    direct_message(confirmation_message)
TypeError: direct_message() missing 1 required positional argument: 'message'
ERROR:discord.app_commands.tree:Ignoring exception in command 'rate_user'
Traceback (most recent call last):
  File "D:\OneDrive\Documents\Projets\DiscordBot_TradingCards\bot.py", line 585, in rate_user
    direct_message(confirmation_message)
TypeError: direct_message() missing 1 required positional argument: 'message'

During handling of the above exception, another exception occurred:

Traceback (most recent call last):
  File "C:\Users\Lupink\AppData\Local\Programs\Python\Python311\Lib\site-packages\discord\app_commands\commands.py", line 828, in _do_call
    return await self._callback(interaction, **params)  # type: ignore
           ^^^^^^^^^^^^^^^^^^^^^^^^^^^^^^^^^^^^^^^^^^^
  File "D:\OneDrive\Documents\Projets\DiscordBot_TradingCards\bot.py", line 589, in rate_user
    await interaction.response.send_message("Une erreur est survenue lors de l'exécution de la commande.", ephemeral=True)
  File "C:\Users\Lupink\AppData\Local\Programs\Python\Python311\Lib\site-packages\discord\interactions.py", line 774, in send_message
    raise InteractionResponded(self._parent)
discord.errors.InteractionResponded: This interaction has already been responded to before

The above exception was the direct cause of the following exception:

Traceback (most recent call last):
  File "C:\Users\Lupink\AppData\Local\Programs\Python\Python311\Lib\site-packages\discord\app_commands\tree.py", line 1248, in _call
    await command._invoke_with_namespace(interaction, namespace)
  File "C:\Users\Lupink\AppData\Local\Programs\Python\Python311\Lib\site-packages\discord\app_commands\commands.py", line 853, in _invoke_with_namespace
    return await self._do_call(interaction, transformed_values)
           ^^^^^^^^^^^^^^^^^^^^^^^^^^^^^^^^^^^^^^^^^^^^^^^^^^^^
  File "C:\Users\Lupink\AppData\Local\Programs\Python\Python311\Lib\site-packages\discord\app_commands\commands.py", line 846, in _do_call
    raise CommandInvokeError(self, e) from e
discord.app_commands.errors.CommandInvokeError: Command 'rate_user' raised an exception: InteractionResponded: This interaction has already been responded to before
WARNING:discord.client:PyNaCl is not installed, voice will NOT be supported
INFO:discord.client:logging in using static token
INFO:discord.gateway:Shard ID None has connected to Gateway (Session ID: 2225e410604b1c3ff85b0d2211e90bd6).
INFO:root:We have logged in as TestTrade#2680.
INFO:root:La commande /rate_user a été exécutée.
ERROR:root:La commande /rate_user a échoué :
Traceback (most recent call last):
  File "D:\OneDrive\Documents\Projets\DiscordBot_TradingCards\bot.py", line 583, in rate_user
    direct_message(confirmation_message)
TypeError: direct_message() missing 1 required positional argument: 'message'
WARNING:discord.client:PyNaCl is not installed, voice will NOT be supported
INFO:discord.client:logging in using static token
INFO:discord.gateway:Shard ID None has connected to Gateway (Session ID: 5653b7e414182ac76907f1424c719a33).
INFO:root:We have logged in as TestTrade#2680.
INFO:root:La commande /rate_user a été exécutée.
ERROR:root:La commande /rate_user a échoué :
Traceback (most recent call last):
  File "D:\OneDrive\Documents\Projets\DiscordBot_TradingCards\bot.py", line 583, in rate_user
    direct_message(confirmation_message)
TypeError: direct_message() missing 1 required positional argument: 'interaction'
WARNING:discord.client:PyNaCl is not installed, voice will NOT be supported
INFO:discord.client:logging in using static token
INFO:discord.gateway:Shard ID None has connected to Gateway (Session ID: fcc79ee6a86b42bb05f5aa5571d7a127).
INFO:root:We have logged in as TestTrade#2680.
INFO:root:La commande /rate_user a été exécutée.
WARNING:discord.client:PyNaCl is not installed, voice will NOT be supported
INFO:discord.client:logging in using static token
INFO:discord.gateway:Shard ID None has connected to Gateway (Session ID: d4d8b9462f33eac1ec9090febd23a70d).
INFO:root:We have logged in as TestTrade#2680.
INFO:root:La commande /rate_user a été exécutée.
WARNING:discord.client:PyNaCl is not installed, voice will NOT be supported
INFO:discord.client:logging in using static token
INFO:discord.gateway:Shard ID None has connected to Gateway (Session ID: c97710764b3e19e03c6d3d8a08c5a61d).
INFO:root:We have logged in as TestTrade#2680.
INFO:root:La commande /rate_user a été exécutée.
ERROR:root:La commande /rate_user a échoué :
Traceback (most recent call last):
  File "D:\OneDrive\Documents\Projets\DiscordBot_TradingCards\bot.py", line 583, in rate_user
    direct_message(interaction, confirmation_message)
TypeError: direct_message() takes 1 positional argument but 2 were given
WARNING:discord.client:PyNaCl is not installed, voice will NOT be supported
INFO:discord.client:logging in using static token
INFO:discord.gateway:Shard ID None has connected to Gateway (Session ID: 2266edb3957b459b0e24a3ed51febe10).
INFO:root:La commande /rate_user a été exécutée.
INFO:root:We have logged in as TestTrade#2680.
WARNING:discord.client:PyNaCl is not installed, voice will NOT be supported
INFO:discord.client:logging in using static token
INFO:discord.gateway:Shard ID None has connected to Gateway (Session ID: 80a44168fc92a083c12ea560fccad1c0).
INFO:root:We have logged in as TestTrade#2680.
INFO:root:La commande /rate_user a été exécutée.
ERROR:root:La commande /rate_user a échoué :
Traceback (most recent call last):
  File "D:\OneDrive\Documents\Projets\DiscordBot_TradingCards\bot.py", line 583, in rate_user
    await direct_message(confirmation_message)
  File "D:\OneDrive\Documents\Projets\DiscordBot_TradingCards\functions.py", line 183, in direct_message
    interaction = await interaction.user.create_dm()
                        ^^^^^^^^^^^^^^^^^^^^^^^^^^
AttributeError: 'member_descriptor' object has no attribute 'create_dm'
WARNING:discord.client:PyNaCl is not installed, voice will NOT be supported
INFO:discord.client:logging in using static token
INFO:discord.gateway:Shard ID None has connected to Gateway (Session ID: a75fe6439d283c7573b890dc8dbda9c2).
INFO:root:We have logged in as TestTrade#2680.
INFO:root:La commande /rate_user a été exécutée.
ERROR:root:La commande /rate_user a échoué :
Traceback (most recent call last):
  File "D:\OneDrive\Documents\Projets\DiscordBot_TradingCards\bot.py", line 583, in rate_user
    await direct_message(confirmation_message)
          ^^^^^^^^^^^^^^^^^^^^^^^^^^^^^^^^^^^^
TypeError: direct_message() missing 1 required positional argument: 'message'
WARNING:discord.client:PyNaCl is not installed, voice will NOT be supported
INFO:discord.client:logging in using static token
INFO:discord.gateway:Shard ID None has connected to Gateway (Session ID: 40d8adcc0981a006e0fad63df811c1d0).
INFO:root:We have logged in as TestTrade#2680.
INFO:root:La commande /rate_user a été exécutée.
ERROR:root:La commande /rate_user a échoué :
Traceback (most recent call last):
  File "D:\OneDrive\Documents\Projets\DiscordBot_TradingCards\bot.py", line 583, in rate_user
    await direct_message(evaluated_user, confirmation_message)
  File "D:\OneDrive\Documents\Projets\DiscordBot_TradingCards\functions.py", line 182, in direct_message
    dm_channel = await user.create_dm()
                       ^^^^^^^^^^^^^^
AttributeError: 'User' object has no attribute 'create_dm'
WARNING:discord.client:PyNaCl is not installed, voice will NOT be supported
INFO:discord.client:logging in using static token
INFO:discord.gateway:Shard ID None has connected to Gateway (Session ID: 00d26fee462eaf434d814c770eaaf049).
INFO:root:We have logged in as TestTrade#2680.
INFO:root:La commande /rate_user a été exécutée.
ERROR:root:La commande /rate_user a échoué :
Traceback (most recent call last):
  File "D:\OneDrive\Documents\Projets\DiscordBot_TradingCards\bot.py", line 583, in rate_user
    await direct_message(evaluated_user, confirmation_message)
  File "D:\OneDrive\Documents\Projets\DiscordBot_TradingCards\functions.py", line 182, in direct_message
    dm_channel = await member.create_dm()
                       ^^^^^^^^^^^^^^^^
AttributeError: 'User' object has no attribute 'create_dm'
WARNING:discord.client:PyNaCl is not installed, voice will NOT be supported
INFO:discord.client:logging in using static token
INFO:discord.gateway:Shard ID None has connected to Gateway (Session ID: a3425a01e55fd42c0709dbc5a5ae2517).
INFO:root:We have logged in as TestTrade#2680.
INFO:root:La commande /rate_user a été exécutée.
ERROR:root:La commande /rate_user a échoué :
Traceback (most recent call last):
  File "D:\OneDrive\Documents\Projets\DiscordBot_TradingCards\bot.py", line 551, in rate_user
    users = load_users()  # Charger les utilisateurs à partir du fichier JSON
            ^^^^^^^^^^
NameError: name 'load_users' is not defined
INFO:discord.client:logging in using static token
INFO:discord.gateway:Shard ID None has connected to Gateway (Session ID: 71d8b93598ca759a44d093aaed4bd754).
WARNING:discord.client:PyNaCl is not installed, voice will NOT be supported
INFO:discord.client:logging in using static token
INFO:discord.gateway:Shard ID None has connected to Gateway (Session ID: a9cc023bcc928c35971fb6456b8fe547).
INFO:root:We have logged in as TestTrade#2680.
INFO:root:La commande /rate_user a été exécutée.
ERROR:root:La commande /rate_user a échoué :
Traceback (most recent call last):
  File "D:\OneDrive\Documents\Projets\DiscordBot_TradingCards\bot.py", line 589, in rate_user
    await direct_message(evaluated_user, confirmation_message)
  File "D:\OneDrive\Documents\Projets\DiscordBot_TradingCards\bot.py", line 54, in direct_message
    to = await client.fetch_user(int(user))
                                 ^^^^^^^^^
TypeError: int() argument must be a string, a bytes-like object or a real number, not 'User'
WARNING:discord.client:PyNaCl is not installed, voice will NOT be supported
INFO:discord.client:logging in using static token
INFO:discord.gateway:Shard ID None has connected to Gateway (Session ID: d22654341e0960b155f8f84a33c26db2).
INFO:root:We have logged in as TestTrade#2680.
INFO:root:La commande /rate_user a été exécutée.
ERROR:root:La commande /rate_user a échoué :
Traceback (most recent call last):
  File "D:\OneDrive\Documents\Projets\DiscordBot_TradingCards\bot.py", line 589, in rate_user
    await direct_message(evaluated_user, confirmation_message)
  File "D:\OneDrive\Documents\Projets\DiscordBot_TradingCards\bot.py", line 54, in direct_message
    to = await client.fetch_user(int(user.id))
                                     ^^^^^^^
AttributeError: 'User' object has no attribute 'id'
WARNING:discord.client:PyNaCl is not installed, voice will NOT be supported
INFO:discord.client:logging in using static token
INFO:discord.gateway:Shard ID None has connected to Gateway (Session ID: 5ed021bd4e939059a56e76ea85a11582).
INFO:root:We have logged in as TestTrade#2680.
INFO:root:La commande /rate_user a été exécutée.
WARNING:discord.client:PyNaCl is not installed, voice will NOT be supported
INFO:discord.client:logging in using static token
INFO:discord.gateway:Shard ID None has connected to Gateway (Session ID: 115a6d5c28a0e949a0a38e85e6a46e59).
INFO:root:We have logged in as TestTrade#2680.
INFO:root:La commande /rate_user a été exécutée.
WARNING:discord.client:PyNaCl is not installed, voice will NOT be supported
INFO:discord.client:logging in using static token
INFO:discord.gateway:Shard ID None has connected to Gateway (Session ID: 00e519a2941569cc1b8eb412e28abc92).
INFO:root:We have logged in as TestTrade#2680.
WARNING:discord.client:PyNaCl is not installed, voice will NOT be supported
INFO:discord.client:logging in using static token
INFO:discord.gateway:Shard ID None has connected to Gateway (Session ID: ec2ee96c4b996bcccd9d0458cf2fa639).
INFO:root:La commande /rate_user a été exécutée.
ERROR:root:La commande /rate_user a échoué :
Traceback (most recent call last):
  File "D:\OneDrive\Documents\Projets\DiscordBot_TradingCards\bot.py", line 620, in rate_user
    await confirm_exchange(evaluated_user_id, evaluation)
  File "D:\OneDrive\Documents\Projets\DiscordBot_TradingCards\bot.py", line 557, in confirm_exchange
    await user.send(confirmation_message)
          ^^^^^^^^^
AttributeError: 'str' object has no attribute 'send'
ERROR:discord.app_commands.tree:Ignoring exception in command 'rate_user'
Traceback (most recent call last):
  File "D:\OneDrive\Documents\Projets\DiscordBot_TradingCards\bot.py", line 620, in rate_user
    await confirm_exchange(evaluated_user_id, evaluation)
  File "D:\OneDrive\Documents\Projets\DiscordBot_TradingCards\bot.py", line 557, in confirm_exchange
    await user.send(confirmation_message)
          ^^^^^^^^^
AttributeError: 'str' object has no attribute 'send'

During handling of the above exception, another exception occurred:

Traceback (most recent call last):
  File "C:\Users\Lupink\AppData\Local\Programs\Python\Python311\Lib\site-packages\discord\app_commands\commands.py", line 828, in _do_call
    return await self._callback(interaction, **params)  # type: ignore
           ^^^^^^^^^^^^^^^^^^^^^^^^^^^^^^^^^^^^^^^^^^^
  File "D:\OneDrive\Documents\Projets\DiscordBot_TradingCards\bot.py", line 624, in rate_user
    await interaction.response.send_message("Une erreur est survenue lors de l'exécution de la commande.", ephemeral=True)
  File "C:\Users\Lupink\AppData\Local\Programs\Python\Python311\Lib\site-packages\discord\interactions.py", line 774, in send_message
    raise InteractionResponded(self._parent)
discord.errors.InteractionResponded: This interaction has already been responded to before

The above exception was the direct cause of the following exception:

Traceback (most recent call last):
  File "C:\Users\Lupink\AppData\Local\Programs\Python\Python311\Lib\site-packages\discord\app_commands\tree.py", line 1248, in _call
    await command._invoke_with_namespace(interaction, namespace)
  File "C:\Users\Lupink\AppData\Local\Programs\Python\Python311\Lib\site-packages\discord\app_commands\commands.py", line 853, in _invoke_with_namespace
    return await self._do_call(interaction, transformed_values)
           ^^^^^^^^^^^^^^^^^^^^^^^^^^^^^^^^^^^^^^^^^^^^^^^^^^^^
  File "C:\Users\Lupink\AppData\Local\Programs\Python\Python311\Lib\site-packages\discord\app_commands\commands.py", line 846, in _do_call
    raise CommandInvokeError(self, e) from e
discord.app_commands.errors.CommandInvokeError: Command 'rate_user' raised an exception: InteractionResponded: This interaction has already been responded to before
INFO:root:We have logged in as TestTrade#2680.
WARNING:discord.client:PyNaCl is not installed, voice will NOT be supported
INFO:discord.client:logging in using static token
INFO:discord.gateway:Shard ID None has connected to Gateway (Session ID: 01364310a9a321148e61e86cd0ea555c).
INFO:root:We have logged in as TestTrade#2680.
WARNING:discord.client:PyNaCl is not installed, voice will NOT be supported
INFO:discord.client:logging in using static token
INFO:discord.gateway:Shard ID None has connected to Gateway (Session ID: 45444bbd8182cdc8692329b6d6eb3e63).
INFO:root:La commande /rate_user a été exécutée.
WARNING:discord.client:PyNaCl is not installed, voice will NOT be supported
INFO:discord.client:logging in using static token
INFO:discord.gateway:Shard ID None has connected to Gateway (Session ID: 5dd528b07f763beae18d8e9a27208d7d).
INFO:root:La commande /rate_user a été exécutée.
INFO:root:We have logged in as TestTrade#2680.
ERROR:root:La commande /rate_user a échoué :
Traceback (most recent call last):
  File "C:\Users\Lupink\AppData\Local\Programs\Python\Python311\Lib\asyncio\tasks.py", line 490, in wait_for
    return fut.result()
           ^^^^^^^^^^^^
asyncio.exceptions.CancelledError

The above exception was the direct cause of the following exception:

Traceback (most recent call last):
  File "D:\OneDrive\Documents\Projets\DiscordBot_TradingCards\bot.py", line 565, in confirm_exchange
    response_message = await client.wait_for('message', check=check_response, timeout=60)
                       ^^^^^^^^^^^^^^^^^^^^^^^^^^^^^^^^^^^^^^^^^^^^^^^^^^^^^^^^^^^^^^^^^^
  File "C:\Users\Lupink\AppData\Local\Programs\Python\Python311\Lib\asyncio\tasks.py", line 492, in wait_for
    raise exceptions.TimeoutError() from exc
TimeoutError

During handling of the above exception, another exception occurred:

Traceback (most recent call last):
  File "D:\OneDrive\Documents\Projets\DiscordBot_TradingCards\bot.py", line 622, in rate_user
    await confirm_exchange(evaluated_user_id, evaluation)
  File "D:\OneDrive\Documents\Projets\DiscordBot_TradingCards\bot.py", line 576, in confirm_exchange
    await user.send("Le délai de confirmation a expiré. Votre évaluation est enregistrée, mais l'échange n'a pas été confirmé.")
          ^^^^^^^^^
AttributeError: 'str' object has no attribute 'send'
ERROR:discord.app_commands.tree:Ignoring exception in command 'rate_user'
Traceback (most recent call last):
  File "C:\Users\Lupink\AppData\Local\Programs\Python\Python311\Lib\asyncio\tasks.py", line 490, in wait_for
    return fut.result()
           ^^^^^^^^^^^^
asyncio.exceptions.CancelledError

The above exception was the direct cause of the following exception:

Traceback (most recent call last):
  File "D:\OneDrive\Documents\Projets\DiscordBot_TradingCards\bot.py", line 565, in confirm_exchange
    response_message = await client.wait_for('message', check=check_response, timeout=60)
                       ^^^^^^^^^^^^^^^^^^^^^^^^^^^^^^^^^^^^^^^^^^^^^^^^^^^^^^^^^^^^^^^^^^
  File "C:\Users\Lupink\AppData\Local\Programs\Python\Python311\Lib\asyncio\tasks.py", line 492, in wait_for
    raise exceptions.TimeoutError() from exc
TimeoutError

During handling of the above exception, another exception occurred:

Traceback (most recent call last):
  File "D:\OneDrive\Documents\Projets\DiscordBot_TradingCards\bot.py", line 622, in rate_user
    await confirm_exchange(evaluated_user_id, evaluation)
  File "D:\OneDrive\Documents\Projets\DiscordBot_TradingCards\bot.py", line 576, in confirm_exchange
    await user.send("Le délai de confirmation a expiré. Votre évaluation est enregistrée, mais l'échange n'a pas été confirmé.")
          ^^^^^^^^^
AttributeError: 'str' object has no attribute 'send'

During handling of the above exception, another exception occurred:

Traceback (most recent call last):
  File "C:\Users\Lupink\AppData\Local\Programs\Python\Python311\Lib\site-packages\discord\app_commands\commands.py", line 828, in _do_call
    return await self._callback(interaction, **params)  # type: ignore
           ^^^^^^^^^^^^^^^^^^^^^^^^^^^^^^^^^^^^^^^^^^^
  File "D:\OneDrive\Documents\Projets\DiscordBot_TradingCards\bot.py", line 626, in rate_user
    await interaction.response.send_message("Une erreur est survenue lors de l'exécution de la commande.", ephemeral=True)
  File "C:\Users\Lupink\AppData\Local\Programs\Python\Python311\Lib\site-packages\discord\interactions.py", line 774, in send_message
    raise InteractionResponded(self._parent)
discord.errors.InteractionResponded: This interaction has already been responded to before

The above exception was the direct cause of the following exception:

Traceback (most recent call last):
  File "C:\Users\Lupink\AppData\Local\Programs\Python\Python311\Lib\site-packages\discord\app_commands\tree.py", line 1248, in _call
    await command._invoke_with_namespace(interaction, namespace)
  File "C:\Users\Lupink\AppData\Local\Programs\Python\Python311\Lib\site-packages\discord\app_commands\commands.py", line 853, in _invoke_with_namespace
    return await self._do_call(interaction, transformed_values)
           ^^^^^^^^^^^^^^^^^^^^^^^^^^^^^^^^^^^^^^^^^^^^^^^^^^^^
  File "C:\Users\Lupink\AppData\Local\Programs\Python\Python311\Lib\site-packages\discord\app_commands\commands.py", line 846, in _do_call
    raise CommandInvokeError(self, e) from e
discord.app_commands.errors.CommandInvokeError: Command 'rate_user' raised an exception: InteractionResponded: This interaction has already been responded to before
WARNING:discord.client:PyNaCl is not installed, voice will NOT be supported
INFO:discord.client:logging in using static token
INFO:discord.gateway:Shard ID None has connected to Gateway (Session ID: e0896b310dd5b470d8d64ad767a0645a).
INFO:root:We have logged in as TestTrade#2680.
INFO:root:La commande /rate_user a été exécutée.
INFO:root:en attente de confirmation de l'échange.
ERROR:root:La commande /rate_user a échoué :
Traceback (most recent call last):
  File "C:\Users\Lupink\AppData\Local\Programs\Python\Python311\Lib\asyncio\tasks.py", line 490, in wait_for
    return fut.result()
           ^^^^^^^^^^^^
asyncio.exceptions.CancelledError

The above exception was the direct cause of the following exception:

Traceback (most recent call last):
  File "D:\OneDrive\Documents\Projets\DiscordBot_TradingCards\bot.py", line 566, in confirm_exchange
    response_message = await client.wait_for('message', check=check_response, timeout=60)
                       ^^^^^^^^^^^^^^^^^^^^^^^^^^^^^^^^^^^^^^^^^^^^^^^^^^^^^^^^^^^^^^^^^^
  File "C:\Users\Lupink\AppData\Local\Programs\Python\Python311\Lib\asyncio\tasks.py", line 492, in wait_for
    raise exceptions.TimeoutError() from exc
TimeoutError

During handling of the above exception, another exception occurred:

Traceback (most recent call last):
  File "D:\OneDrive\Documents\Projets\DiscordBot_TradingCards\bot.py", line 623, in rate_user
    await confirm_exchange(evaluated_user_id, evaluation)
  File "D:\OneDrive\Documents\Projets\DiscordBot_TradingCards\bot.py", line 577, in confirm_exchange
    await user.followup.send("Le délai de confirmation a expiré. Votre évaluation est enregistrée, mais l'échange n'a pas été confirmé.")
          ^^^^^^^^^^^^^
AttributeError: 'str' object has no attribute 'followup'
ERROR:discord.app_commands.tree:Ignoring exception in command 'rate_user'
Traceback (most recent call last):
  File "C:\Users\Lupink\AppData\Local\Programs\Python\Python311\Lib\asyncio\tasks.py", line 490, in wait_for
    return fut.result()
           ^^^^^^^^^^^^
asyncio.exceptions.CancelledError

The above exception was the direct cause of the following exception:

Traceback (most recent call last):
  File "D:\OneDrive\Documents\Projets\DiscordBot_TradingCards\bot.py", line 566, in confirm_exchange
    response_message = await client.wait_for('message', check=check_response, timeout=60)
                       ^^^^^^^^^^^^^^^^^^^^^^^^^^^^^^^^^^^^^^^^^^^^^^^^^^^^^^^^^^^^^^^^^^
  File "C:\Users\Lupink\AppData\Local\Programs\Python\Python311\Lib\asyncio\tasks.py", line 492, in wait_for
    raise exceptions.TimeoutError() from exc
TimeoutError

During handling of the above exception, another exception occurred:

Traceback (most recent call last):
  File "D:\OneDrive\Documents\Projets\DiscordBot_TradingCards\bot.py", line 623, in rate_user
    await confirm_exchange(evaluated_user_id, evaluation)
  File "D:\OneDrive\Documents\Projets\DiscordBot_TradingCards\bot.py", line 577, in confirm_exchange
    await user.followup.send("Le délai de confirmation a expiré. Votre évaluation est enregistrée, mais l'échange n'a pas été confirmé.")
          ^^^^^^^^^^^^^
AttributeError: 'str' object has no attribute 'followup'

During handling of the above exception, another exception occurred:

Traceback (most recent call last):
  File "C:\Users\Lupink\AppData\Local\Programs\Python\Python311\Lib\site-packages\discord\app_commands\commands.py", line 828, in _do_call
    return await self._callback(interaction, **params)  # type: ignore
           ^^^^^^^^^^^^^^^^^^^^^^^^^^^^^^^^^^^^^^^^^^^
  File "D:\OneDrive\Documents\Projets\DiscordBot_TradingCards\bot.py", line 627, in rate_user
    await interaction.response.send_message("Une erreur est survenue lors de l'exécution de la commande.", ephemeral=True)
  File "C:\Users\Lupink\AppData\Local\Programs\Python\Python311\Lib\site-packages\discord\interactions.py", line 774, in send_message
    raise InteractionResponded(self._parent)
discord.errors.InteractionResponded: This interaction has already been responded to before

The above exception was the direct cause of the following exception:

Traceback (most recent call last):
  File "C:\Users\Lupink\AppData\Local\Programs\Python\Python311\Lib\site-packages\discord\app_commands\tree.py", line 1248, in _call
    await command._invoke_with_namespace(interaction, namespace)
  File "C:\Users\Lupink\AppData\Local\Programs\Python\Python311\Lib\site-packages\discord\app_commands\commands.py", line 853, in _invoke_with_namespace
    return await self._do_call(interaction, transformed_values)
           ^^^^^^^^^^^^^^^^^^^^^^^^^^^^^^^^^^^^^^^^^^^^^^^^^^^^
  File "C:\Users\Lupink\AppData\Local\Programs\Python\Python311\Lib\site-packages\discord\app_commands\commands.py", line 846, in _do_call
    raise CommandInvokeError(self, e) from e
discord.app_commands.errors.CommandInvokeError: Command 'rate_user' raised an exception: InteractionResponded: This interaction has already been responded to before
WARNING:discord.client:PyNaCl is not installed, voice will NOT be supported
INFO:discord.client:logging in using static token
INFO:discord.gateway:Shard ID None has connected to Gateway (Session ID: fb41eb62b9b8363c52960ad09cebfb7d).
INFO:root:We have logged in as TestTrade#2680.
INFO:root:La commande /rate_user a été exécutée.
INFO:root:La commande /show_evaluations a été exécutée.
INFO:root:La commande /rate_user a été exécutée.
WARNING:discord.client:PyNaCl is not installed, voice will NOT be supported
INFO:discord.client:logging in using static token
INFO:discord.gateway:Shard ID None has connected to Gateway (Session ID: 288e2e0b07060f347ff1385845be998e).
INFO:root:We have logged in as TestTrade#2680.
INFO:root:La commande /rate_user a été exécutée.
WARNING:discord.client:PyNaCl is not installed, voice will NOT be supported
INFO:discord.client:logging in using static token
INFO:discord.gateway:Shard ID None has connected to Gateway (Session ID: 6fdcfba801b688a60ed261d8dcfae2f9).
INFO:root:We have logged in as TestTrade#2680.
INFO:root:La commande /rate_user a été exécutée.
ERROR:root:La commande /rate_user a échoué :
Traceback (most recent call last):
  File "D:\OneDrive\Documents\Projets\DiscordBot_TradingCards\bot.py", line 577, in rate_user
    evaluated_user.add_evaluation(evaluation)
    ^^^^^^^^^^^^^^^^^^^^^^^^^^^^^
AttributeError: 'Member' object has no attribute 'add_evaluation'
WARNING:discord.client:PyNaCl is not installed, voice will NOT be supported
INFO:discord.client:logging in using static token
INFO:discord.gateway:Shard ID None has connected to Gateway (Session ID: 9a33e7030ddf7c15cf1b062e1ce5ab06).
INFO:root:We have logged in as TestTrade#2680.
INFO:root:La commande /rate_user a été exécutée.
ERROR:root:La commande /rate_user a échoué :
Traceback (most recent call last):
  File "D:\OneDrive\Documents\Projets\DiscordBot_TradingCards\bot.py", line 588, in rate_user
    await direct_message(evaluated_user_id, confirmation_message)
  File "D:\OneDrive\Documents\Projets\DiscordBot_TradingCards\bot.py", line 57, in direct_message
    await to.send(message)
  File "C:\Users\Lupink\AppData\Local\Programs\Python\Python311\Lib\site-packages\discord\abc.py", line 1516, in send
    channel = await self._get_channel()
              ^^^^^^^^^^^^^^^^^^^^^^^^^
  File "C:\Users\Lupink\AppData\Local\Programs\Python\Python311\Lib\site-packages\discord\user.py", line 488, in _get_channel
    ch = await self.create_dm()
         ^^^^^^^^^^^^^^^^^^^^^^
  File "C:\Users\Lupink\AppData\Local\Programs\Python\Python311\Lib\site-packages\discord\user.py", line 530, in create_dm
    data: DMChannelPayload = await state.http.start_private_message(self.id)
                             ^^^^^^^^^^^^^^^^^^^^^^^^^^^^^^^^^^^^^^^^^^^^^^^
  File "C:\Users\Lupink\AppData\Local\Programs\Python\Python311\Lib\site-packages\discord\http.py", line 745, in request
    raise HTTPException(response, data)
discord.errors.HTTPException: 400 Bad Request (error code: 50007): Cannot send messages to this user
ERROR:discord.app_commands.tree:Ignoring exception in command 'rate_user'
Traceback (most recent call last):
  File "D:\OneDrive\Documents\Projets\DiscordBot_TradingCards\bot.py", line 588, in rate_user
    await direct_message(evaluated_user_id, confirmation_message)
  File "D:\OneDrive\Documents\Projets\DiscordBot_TradingCards\bot.py", line 57, in direct_message
    await to.send(message)
  File "C:\Users\Lupink\AppData\Local\Programs\Python\Python311\Lib\site-packages\discord\abc.py", line 1516, in send
    channel = await self._get_channel()
              ^^^^^^^^^^^^^^^^^^^^^^^^^
  File "C:\Users\Lupink\AppData\Local\Programs\Python\Python311\Lib\site-packages\discord\user.py", line 488, in _get_channel
    ch = await self.create_dm()
         ^^^^^^^^^^^^^^^^^^^^^^
  File "C:\Users\Lupink\AppData\Local\Programs\Python\Python311\Lib\site-packages\discord\user.py", line 530, in create_dm
    data: DMChannelPayload = await state.http.start_private_message(self.id)
                             ^^^^^^^^^^^^^^^^^^^^^^^^^^^^^^^^^^^^^^^^^^^^^^^
  File "C:\Users\Lupink\AppData\Local\Programs\Python\Python311\Lib\site-packages\discord\http.py", line 745, in request
    raise HTTPException(response, data)
discord.errors.HTTPException: 400 Bad Request (error code: 50007): Cannot send messages to this user

During handling of the above exception, another exception occurred:

Traceback (most recent call last):
  File "C:\Users\Lupink\AppData\Local\Programs\Python\Python311\Lib\site-packages\discord\app_commands\commands.py", line 828, in _do_call
    return await self._callback(interaction, **params)  # type: ignore
           ^^^^^^^^^^^^^^^^^^^^^^^^^^^^^^^^^^^^^^^^^^^
  File "D:\OneDrive\Documents\Projets\DiscordBot_TradingCards\bot.py", line 593, in rate_user
    await interaction.response.send_message("Une erreur est survenue lors de l'exécution de la commande.", ephemeral=True)
  File "C:\Users\Lupink\AppData\Local\Programs\Python\Python311\Lib\site-packages\discord\interactions.py", line 774, in send_message
    raise InteractionResponded(self._parent)
discord.errors.InteractionResponded: This interaction has already been responded to before

The above exception was the direct cause of the following exception:

Traceback (most recent call last):
  File "C:\Users\Lupink\AppData\Local\Programs\Python\Python311\Lib\site-packages\discord\app_commands\tree.py", line 1248, in _call
    await command._invoke_with_namespace(interaction, namespace)
  File "C:\Users\Lupink\AppData\Local\Programs\Python\Python311\Lib\site-packages\discord\app_commands\commands.py", line 853, in _invoke_with_namespace
    return await self._do_call(interaction, transformed_values)
           ^^^^^^^^^^^^^^^^^^^^^^^^^^^^^^^^^^^^^^^^^^^^^^^^^^^^
  File "C:\Users\Lupink\AppData\Local\Programs\Python\Python311\Lib\site-packages\discord\app_commands\commands.py", line 846, in _do_call
    raise CommandInvokeError(self, e) from e
discord.app_commands.errors.CommandInvokeError: Command 'rate_user' raised an exception: InteractionResponded: This interaction has already been responded to before
WARNING:discord.client:PyNaCl is not installed, voice will NOT be supported
INFO:discord.client:logging in using static token
INFO:discord.gateway:Shard ID None has connected to Gateway (Session ID: 2b112ec0edf37073e4af9842474abb4c).
INFO:root:We have logged in as TestTrade#2680.
INFO:root:La commande /rate_user a été exécutée.
ERROR:root:La commande /rate_user a échoué :
Traceback (most recent call last):
  File "D:\OneDrive\Documents\Projets\DiscordBot_TradingCards\bot.py", line 586, in rate_user
    await direct_message(evaluated_user_id, confirmation_message)
  File "D:\OneDrive\Documents\Projets\DiscordBot_TradingCards\bot.py", line 57, in direct_message
    await to.send(message)
  File "C:\Users\Lupink\AppData\Local\Programs\Python\Python311\Lib\site-packages\discord\abc.py", line 1516, in send
    channel = await self._get_channel()
              ^^^^^^^^^^^^^^^^^^^^^^^^^
  File "C:\Users\Lupink\AppData\Local\Programs\Python\Python311\Lib\site-packages\discord\user.py", line 488, in _get_channel
    ch = await self.create_dm()
         ^^^^^^^^^^^^^^^^^^^^^^
  File "C:\Users\Lupink\AppData\Local\Programs\Python\Python311\Lib\site-packages\discord\user.py", line 530, in create_dm
    data: DMChannelPayload = await state.http.start_private_message(self.id)
                             ^^^^^^^^^^^^^^^^^^^^^^^^^^^^^^^^^^^^^^^^^^^^^^^
  File "C:\Users\Lupink\AppData\Local\Programs\Python\Python311\Lib\site-packages\discord\http.py", line 745, in request
    raise HTTPException(response, data)
discord.errors.HTTPException: 400 Bad Request (error code: 50007): Cannot send messages to this user
INFO:root:La commande /rate_user a été exécutée.
WARNING:discord.client:PyNaCl is not installed, voice will NOT be supported
INFO:discord.client:logging in using static token
INFO:discord.gateway:Shard ID None has connected to Gateway (Session ID: ad53433cb784757ddace5bde2c4c648c).
INFO:root:We have logged in as TestTrade#2680.
INFO:root:La commande /rate_user a été exécutée.
INFO:root:La commande /show_evaluations a été exécutée.
INFO:root:La commande /show_available_cards a été exécutée.
INFO:root:La commande /show_selected_cards a été exécutée.
INFO:root:La commande /show_selected_cards a été exécutée.
INFO:root:La commande /show_selected_cards a été exécutée.
INFO:root:La commande /search_card a été exécutée.
INFO:root:La commande /search_card a été exécutée.
INFO:root:La commande /search_card a été exécutée.
ERROR:root:La commande /search_card a échoué :
Traceback (most recent call last):
  File "D:\OneDrive\Documents\Projets\DiscordBot_TradingCards\bot.py", line 177, in search_card
    await interaction.response.send_message(f"La carte spécifiée '{card_identifier}' n'existe pas.", ephemeral=True)
  File "C:\Users\Lupink\AppData\Local\Programs\Python\Python311\Lib\site-packages\discord\interactions.py", line 774, in send_message
    raise InteractionResponded(self._parent)
discord.errors.InteractionResponded: This interaction has already been responded to before
ERROR:discord.app_commands.tree:Ignoring exception in command 'search_card'
Traceback (most recent call last):
  File "D:\OneDrive\Documents\Projets\DiscordBot_TradingCards\bot.py", line 177, in search_card
    await interaction.response.send_message(f"La carte spécifiée '{card_identifier}' n'existe pas.", ephemeral=True)
  File "C:\Users\Lupink\AppData\Local\Programs\Python\Python311\Lib\site-packages\discord\interactions.py", line 774, in send_message
    raise InteractionResponded(self._parent)
discord.errors.InteractionResponded: This interaction has already been responded to before

During handling of the above exception, another exception occurred:

Traceback (most recent call last):
  File "C:\Users\Lupink\AppData\Local\Programs\Python\Python311\Lib\site-packages\discord\app_commands\commands.py", line 828, in _do_call
    return await self._callback(interaction, **params)  # type: ignore
           ^^^^^^^^^^^^^^^^^^^^^^^^^^^^^^^^^^^^^^^^^^^
  File "D:\OneDrive\Documents\Projets\DiscordBot_TradingCards\bot.py", line 201, in search_card
    await interaction.response.send_message("Une erreur est survenue lors de l'exécution de la commande.", ephemeral=True)
  File "C:\Users\Lupink\AppData\Local\Programs\Python\Python311\Lib\site-packages\discord\interactions.py", line 774, in send_message
    raise InteractionResponded(self._parent)
discord.errors.InteractionResponded: This interaction has already been responded to before

The above exception was the direct cause of the following exception:

Traceback (most recent call last):
  File "C:\Users\Lupink\AppData\Local\Programs\Python\Python311\Lib\site-packages\discord\app_commands\tree.py", line 1248, in _call
    await command._invoke_with_namespace(interaction, namespace)
  File "C:\Users\Lupink\AppData\Local\Programs\Python\Python311\Lib\site-packages\discord\app_commands\commands.py", line 853, in _invoke_with_namespace
    return await self._do_call(interaction, transformed_values)
           ^^^^^^^^^^^^^^^^^^^^^^^^^^^^^^^^^^^^^^^^^^^^^^^^^^^^
  File "C:\Users\Lupink\AppData\Local\Programs\Python\Python311\Lib\site-packages\discord\app_commands\commands.py", line 846, in _do_call
    raise CommandInvokeError(self, e) from e
discord.app_commands.errors.CommandInvokeError: Command 'search_card' raised an exception: InteractionResponded: This interaction has already been responded to before
INFO:root:La commande /search_card a été exécutée.
ERROR:root:La commande /search_card a échoué :
Traceback (most recent call last):
  File "D:\OneDrive\Documents\Projets\DiscordBot_TradingCards\bot.py", line 186, in search_card
    await interaction.response.send_message(f"{interaction.user.mention} recherche :", embed=embed)
  File "C:\Users\Lupink\AppData\Local\Programs\Python\Python311\Lib\site-packages\discord\interactions.py", line 774, in send_message
    raise InteractionResponded(self._parent)
discord.errors.InteractionResponded: This interaction has already been responded to before
ERROR:discord.app_commands.tree:Ignoring exception in command 'search_card'
Traceback (most recent call last):
  File "D:\OneDrive\Documents\Projets\DiscordBot_TradingCards\bot.py", line 186, in search_card
    await interaction.response.send_message(f"{interaction.user.mention} recherche :", embed=embed)
  File "C:\Users\Lupink\AppData\Local\Programs\Python\Python311\Lib\site-packages\discord\interactions.py", line 774, in send_message
    raise InteractionResponded(self._parent)
discord.errors.InteractionResponded: This interaction has already been responded to before

During handling of the above exception, another exception occurred:

Traceback (most recent call last):
  File "C:\Users\Lupink\AppData\Local\Programs\Python\Python311\Lib\site-packages\discord\app_commands\commands.py", line 828, in _do_call
    return await self._callback(interaction, **params)  # type: ignore
           ^^^^^^^^^^^^^^^^^^^^^^^^^^^^^^^^^^^^^^^^^^^
  File "D:\OneDrive\Documents\Projets\DiscordBot_TradingCards\bot.py", line 201, in search_card
    await interaction.response.send_message("Une erreur est survenue lors de l'exécution de la commande.", ephemeral=True)
  File "C:\Users\Lupink\AppData\Local\Programs\Python\Python311\Lib\site-packages\discord\interactions.py", line 774, in send_message
    raise InteractionResponded(self._parent)
discord.errors.InteractionResponded: This interaction has already been responded to before

The above exception was the direct cause of the following exception:

Traceback (most recent call last):
  File "C:\Users\Lupink\AppData\Local\Programs\Python\Python311\Lib\site-packages\discord\app_commands\tree.py", line 1248, in _call
    await command._invoke_with_namespace(interaction, namespace)
  File "C:\Users\Lupink\AppData\Local\Programs\Python\Python311\Lib\site-packages\discord\app_commands\commands.py", line 853, in _invoke_with_namespace
    return await self._do_call(interaction, transformed_values)
           ^^^^^^^^^^^^^^^^^^^^^^^^^^^^^^^^^^^^^^^^^^^^^^^^^^^^
  File "C:\Users\Lupink\AppData\Local\Programs\Python\Python311\Lib\site-packages\discord\app_commands\commands.py", line 846, in _do_call
    raise CommandInvokeError(self, e) from e
discord.app_commands.errors.CommandInvokeError: Command 'search_card' raised an exception: InteractionResponded: This interaction has already been responded to before
INFO:root:La commande /search_card a été exécutée.
ERROR:root:La commande /search_card a échoué :
Traceback (most recent call last):
  File "D:\OneDrive\Documents\Projets\DiscordBot_TradingCards\bot.py", line 186, in search_card
    await interaction.response.send_message(f"{interaction.user.mention} recherche :", embed=embed)
  File "C:\Users\Lupink\AppData\Local\Programs\Python\Python311\Lib\site-packages\discord\interactions.py", line 774, in send_message
    raise InteractionResponded(self._parent)
discord.errors.InteractionResponded: This interaction has already been responded to before
ERROR:discord.app_commands.tree:Ignoring exception in command 'search_card'
Traceback (most recent call last):
  File "D:\OneDrive\Documents\Projets\DiscordBot_TradingCards\bot.py", line 186, in search_card
    await interaction.response.send_message(f"{interaction.user.mention} recherche :", embed=embed)
  File "C:\Users\Lupink\AppData\Local\Programs\Python\Python311\Lib\site-packages\discord\interactions.py", line 774, in send_message
    raise InteractionResponded(self._parent)
discord.errors.InteractionResponded: This interaction has already been responded to before

During handling of the above exception, another exception occurred:

Traceback (most recent call last):
  File "C:\Users\Lupink\AppData\Local\Programs\Python\Python311\Lib\site-packages\discord\app_commands\commands.py", line 828, in _do_call
    return await self._callback(interaction, **params)  # type: ignore
           ^^^^^^^^^^^^^^^^^^^^^^^^^^^^^^^^^^^^^^^^^^^
  File "D:\OneDrive\Documents\Projets\DiscordBot_TradingCards\bot.py", line 201, in search_card
    await interaction.response.send_message("Une erreur est survenue lors de l'exécution de la commande.", ephemeral=True)
  File "C:\Users\Lupink\AppData\Local\Programs\Python\Python311\Lib\site-packages\discord\interactions.py", line 774, in send_message
    raise InteractionResponded(self._parent)
discord.errors.InteractionResponded: This interaction has already been responded to before

The above exception was the direct cause of the following exception:

Traceback (most recent call last):
  File "C:\Users\Lupink\AppData\Local\Programs\Python\Python311\Lib\site-packages\discord\app_commands\tree.py", line 1248, in _call
    await command._invoke_with_namespace(interaction, namespace)
  File "C:\Users\Lupink\AppData\Local\Programs\Python\Python311\Lib\site-packages\discord\app_commands\commands.py", line 853, in _invoke_with_namespace
    return await self._do_call(interaction, transformed_values)
           ^^^^^^^^^^^^^^^^^^^^^^^^^^^^^^^^^^^^^^^^^^^^^^^^^^^^
  File "C:\Users\Lupink\AppData\Local\Programs\Python\Python311\Lib\site-packages\discord\app_commands\commands.py", line 846, in _do_call
    raise CommandInvokeError(self, e) from e
discord.app_commands.errors.CommandInvokeError: Command 'search_card' raised an exception: InteractionResponded: This interaction has already been responded to before
INFO:root:La commande /search_card a été exécutée.
INFO:root:La commande /trade_cards a été exécutée.
INFO:root:La commande /trade_cards a été exécutée.
INFO:root:La commande /search_card a été exécutée.
INFO:root:La commande /search_card a été exécutée.
INFO:root:La commande /search_card a été exécutée.
INFO:root:La commande /show_trades a été exécutée.
INFO:root:La commande /show_trades a été exécutée.
INFO:root:La commande /remove_card a été exécutée.
INFO:root:La commande /profile a été exécutée.
INFO:root:La commande /leaderboard a été exécutée.
INFO:root:La commande /stats a été exécutée.
INFO:root:La commande /rate_user a été exécutée.
INFO:root:La commande /show_evaluations a été exécutée.
INFO:root:La commande /reset a été exécutée.
INFO:root:La commande /reset a été exécutée.
INFO:root:La commande /reset a été exécutée.
INFO:root:La commande /rate_user a été exécutée.
INFO:root:La commande /reset a été exécutée.
INFO:root:La commande /delete_profile a été exécutée.
